<?xml version="1.0" ?>
<robot name="PointMass">
  <link name="base"/>
  <link name="base_x"/>
  <link name="base_xy"/>
  <link name="point">
    <inertial>
      <mass value="1"/>
      <inertia ixx="0" ixy="0" ixz="0" iyy="0" iyz="0" izz="0"/>
    </inertial>
    <visual>
      <geometry>
        <sphere radius="0.01"/>
      </geometry>
      <material name="green">
        <color rgba="0 1 0 1"/>
      </material>
    </visual>
    <collision>
      <origin xyz="0 0 0"/>
      <geometry>
        <sphere radius="0"/>
      </geometry>
    </collision>
  </link>
  <joint name="planar_x" type="prismatic">
    <parent link="base"/>
    <child link="base_x"/>
    <axis xyz="1 0 0"/>
  </joint>
  <joint name="planar_y" type="prismatic">
    <parent link="base_x"/>
    <child link="base_xy"/>
    <axis xyz="0 1 0"/>
  </joint>  
  <joint name="planar_z" type="prismatic">
    <parent link="base_xy"/>
    <child link="point"/>
    <axis xyz="0 0 1"/>
  </joint>  
</robot>


